try{
    let a;
    console.log(a.length);
    console.log("In Try Block");
}
catch(err){
    console.log("error caught");
}



console.log("After Try Catch Block");